<?xml version="1.0" ?>
<robot name="jacabot" xmlns:xacro="http://www.ros.org/wiki/xacro">

<xacro:include filename="$(find jacabot_description)/urdf/materials.xacro" />
<xacro:include filename="$(find jacabot_description)/urdf/jacabot.trans" />
<!-- <xacro:include filename="$(find jacabot_description)/urdf/jacabot.gazebo" /> -->


<xacro:include filename="$(find jacabot_description)/gazebo/jacabot_materials.gazebo" />
<xacro:include filename="$(find jacabot_description)/gazebo/jacabot_physics.gazebo" />
<xacro:include filename="$(find jacabot_description)/gazebo/jacabot_plugins.gazebo" />
<link name="base_link">
  <inertial>
    <origin rpy="0 0 0" xyz="0.015674415828273155 -2.8128980710952588e-08 0.07127070468579294"/>
    <mass value="2.155372145560495"/>
    <inertia ixx="0.011338" ixy="0.0" ixz="3.4e-05" iyy="0.008818" iyz="-0.0" izz="0.015949"/>
  </inertial>
  <visual>
    <origin rpy="0 0 0" xyz="0 0 0"/>
    <geometry>
      <mesh filename="package://jacabot_description/meshes/base_link.stl" scale="0.001 0.001 0.001"/>
    </geometry>
    <!-- <material name="silver"/> -->
  </visual>
  <collision>
    <origin rpy="0 0 0" xyz="0 0 0"/>
    <geometry>
      <mesh filename="package://jacabot_description/meshes/base_link.stl" scale="0.001 0.001 0.001"/>
    </geometry>
  </collision>
</link>

<link name="lidar_1">
  <inertial>
    <origin rpy="0 0 0" xyz="-0.0022504316269782235 4.50011400247341e-05 0.04507204893353943"/>
    <mass value="5.170546733650495"/>
    <inertia ixx="0.024601" ixy="-7e-06" ixz="2.8e-05" iyy="0.003279" iyz="-3e-06" izz="0.024429"/>
  </inertial>
  <visual>
    <origin rpy="0 0 0" xyz="-0.048389 -0.0 -0.10325"/>
    <geometry>
      <mesh filename="package://jacabot_description/meshes/lidar_1.stl" scale="0.001 0.001 0.001"/>
    </geometry>
    <!-- <material name="silver"/> -->
  </visual>
  <collision>
    <origin rpy="0 0 0" xyz="-0.048389 -0.0 -0.10325"/>
    <geometry>
      <mesh filename="package://jacabot_description/meshes/lidar_1.stl" scale="0.001 0.001 0.001"/>
    </geometry>
  </collision>
</link>

<link name="ball_caster_1">
  <inertial>
    <origin rpy="0 0 0" xyz="0.10500005407994323 1.3527168229998665e-07 -0.017781235122917446"/>
    <mass value="0.11832109888432071"/>
    <inertia ixx="1.2e-05" ixy="-0.0" ixz="-0.0" iyy="1.2e-05" iyz="-0.0" izz="1.3e-05"/>
  </inertial>
  <visual>
    <origin rpy="0 0 0" xyz="-0.0 -0.0 -0.03725"/>
    <geometry>
      <mesh filename="package://jacabot_description/meshes/ball_caster_1.stl" scale="0.001 0.001 0.001"/>
    </geometry>
    <!-- <material name="silver"/> -->
  </visual>
  <collision>
    <origin rpy="0 0 0" xyz="-0.0 -0.0 -0.03725"/>
    <geometry>
      <mesh filename="package://jacabot_description/meshes/ball_caster_1.stl" scale="0.001 0.001 0.001"/>
    </geometry>
  </collision>
</link>

<link name="left_wheel_1">
  <inertial>
    <origin rpy="0 0 0" xyz="6.89208122124023e-07 -0.0025244883476635005 7.730982640175021e-08"/>
    <mass value="0.17466089985318492"/>
    <inertia ixx="0.000128" ixy="0.0" ixz="-0.0" iyy="0.000254" iyz="0.0" izz="0.000128"/>
  </inertial>
  <visual>
    <origin rpy="0 0 0" xyz="0.0 -0.116 -0.045"/>
    <geometry>
      <mesh filename="package://jacabot_description/meshes/left_wheel_1.stl" scale="0.001 0.001 0.001"/>
    </geometry>
    <!-- <material name="silver"/> -->
  </visual>
  <collision>
    <origin rpy="0 0 0" xyz="0.0 -0.116 -0.045"/>
    <geometry>
      <mesh filename="package://jacabot_description/meshes/left_wheel_1.stl" scale="0.001 0.001 0.001"/>
    </geometry>
  </collision>
</link>

<link name="right_wheel_1">
  <inertial>
    <origin rpy="0 0 0" xyz="-7.943571002755334e-08 0.0025244883476652075 -6.907443368259214e-07"/>
    <mass value="0.1746608998531851"/>
    <inertia ixx="0.000128" ixy="0.0" ixz="-0.0" iyy="0.000254" iyz="0.0" izz="0.000128"/>
  </inertial>
  <visual>
    <origin rpy="0 0 0" xyz="0.0 0.116 -0.045"/>
    <geometry>
      <mesh filename="package://jacabot_description/meshes/right_wheel_1.stl" scale="0.001 0.001 0.001"/>
    </geometry>
    <!-- <material name="silver"/> -->
  </visual>
  <collision>
    <origin rpy="0 0 0" xyz="0.0 0.116 -0.045"/>
    <geometry>
      <mesh filename="package://jacabot_description/meshes/right_wheel_1.stl" scale="0.001 0.001 0.001"/>
    </geometry>
  </collision>
</link>

<joint name="lidar_fix" type="fixed">
  <origin rpy="0 0 0" xyz="0.048389 0.0 0.10325"/>
  <parent link="base_link"/>
  <child link="lidar_1"/>
</joint>

<joint name="caster_fix" type="fixed">
  <origin rpy="0 0 0" xyz="0.0 0.0 0.03725"/>
  <parent link="base_link"/>
  <child link="ball_caster_1"/>
</joint>

<joint name="left_wheel_joint" type="continuous">
  <origin rpy="0 0 0" xyz="0.0 0.116 0.045"/>
  <parent link="base_link"/>
  <child link="left_wheel_1"/>
  <axis xyz="0.0 1.0 -0.0"/>
</joint>

<joint name="right_wheel_joint" type="continuous">
  <origin rpy="0 0 0" xyz="0.0 -0.116 0.045"/>
  <parent link="base_link"/>
  <child link="right_wheel_1"/>
  <axis xyz="-0.0 1.0 -0.0"/>
</joint>

</robot>
