<?xml version="1.0" ?>
<robot name="jacabot" xmlns:xacro="http://www.ros.org/wiki/xacro">

<xacro:include filename="$(find jacabot_description)/urdf/materials.xacro" />
<xacro:include filename="$(find jacabot_description)/urdf/jacabot.trans" />
<!-- <xacro:include filename="$(find jacabot_description)/urdf/jacabot.gazebo" /> -->


<xacro:include filename="$(find jacabot_description)/gazebo/jacabot_materials.gazebo" />
<xacro:include filename="$(find jacabot_description)/gazebo/jacabot_physics.gazebo" />
<xacro:include filename="$(find jacabot_description)/gazebo/jacabot_plugins.gazebo" />

<link name="base_link">
  <inertial>
    <origin rpy="0 0 0" xyz="-2.8129093221422423e-08 -0.015674478682352763 0.07127082907629367"/>
    <mass value="2.155363502599137"/>
    <inertia ixx="0.008818" ixy="-0.0" ixz="-0.0" iyy="0.011338" iyz="-3.4e-05" izz="0.015949"/>
  </inertial>
  <visual>
    <origin rpy="0 0 0" xyz="0 0 0"/>
    <geometry>
      <mesh filename="package://jacabot_description/meshes/base_link.stl" scale="0.001 0.001 0.001"/>
    </geometry>
    <material name="silver"/>
  </visual>
  <collision>
    <origin rpy="0 0 0" xyz="0 0 0"/>
    <geometry>
      <mesh filename="package://jacabot_description/meshes/base_link.stl" scale="0.001 0.001 0.001"/>
    </geometry>
  </collision>
</link>

<link name="lidar_1">
  <inertial>
    <origin rpy="0 0 0" xyz="4.522192788972146e-05 0.0022507224363550113 0.04507204964186852"/>
    <mass value="5.170546565587251"/>
    <inertia ixx="0.00328" ixy="7e-06" ixz="-3e-06" iyy="0.024601" iyz="-2.8e-05" izz="0.024429"/>
  </inertial>
  <visual>
    <origin rpy="0 0 0" xyz="0.0 0.048389 -0.10325"/>
    <geometry>
      <mesh filename="package://jacabot_description/meshes/lidar_1.stl" scale="0.001 0.001 0.001"/>
    </geometry>
    <material name="silver"/>
  </visual>
  <collision>
    <origin rpy="0 0 0" xyz="0.0 0.048389 -0.10325"/>
    <geometry>
      <mesh filename="package://jacabot_description/meshes/lidar_1.stl" scale="0.001 0.001 0.001"/>
    </geometry>
  </collision>
</link>

<link name="camera_1">
  <inertial>
    <origin rpy="0 0 0" xyz="-1.977677839289423e-06 -0.07634667276257799 -0.009854879487852894"/>
    <mass value="0.019704301403135695"/>
    <inertia ixx="1e-06" ixy="0.0" ixz="0.0" iyy="1e-06" iyz="0.0" izz="1e-06"/>
  </inertial>
  <visual>
    <origin rpy="0 0 0" xyz="0.0 0.048389 -0.10025"/>
    <geometry>
      <mesh filename="package://jacabot_description/meshes/camera_1.stl" scale="0.001 0.001 0.001"/>
    </geometry>
    <material name="silver"/>
  </visual>
  <collision>
    <origin rpy="0 0 0" xyz="0.0 0.048389 -0.10025"/>
    <geometry>
      <mesh filename="package://jacabot_description/meshes/camera_1.stl" scale="0.001 0.001 0.001"/>
    </geometry>
  </collision>
</link>

<link name="ball_caster_1">
  <inertial>
    <origin rpy="0 0 0" xyz="1.3440264421936125e-07 -0.10500005661939853 -0.017781235021511445"/>
    <mass value="0.11832109459054331"/>
    <inertia ixx="1.2e-05" ixy="0.0" ixz="-0.0" iyy="1.2e-05" iyz="0.0" izz="1.3e-05"/>
  </inertial>
  <visual>
    <origin rpy="0 0 0" xyz="0.0 0.0 -0.03725"/>
    <geometry>
      <mesh filename="package://jacabot_description/meshes/ball_caster_1.stl" scale="0.001 0.001 0.001"/>
    </geometry>
    <material name="silver"/>
  </visual>
  <collision>
    <origin rpy="0 0 0" xyz="0.0 0.0 -0.03725"/>
    <geometry>
      <mesh filename="package://jacabot_description/meshes/ball_caster_1.stl" scale="0.001 0.001 0.001"/>
    </geometry>
  </collision>
</link>

<link name="left_wheel_1">
  <inertial>
    <origin rpy="0 0 0" xyz="-0.0025245376526800006 -2.6468554383153746e-08 -6.907443367495936e-07"/>
    <mass value="0.1746608998531855"/>
    <inertia ixx="0.000254" ixy="0.0" ixz="-0.0" iyy="0.000128" iyz="-0.0" izz="0.000128"/>
  </inertial>
  <visual>
    <origin rpy="0 0 0" xyz="-0.116 -0.0 -0.045"/>
    <geometry>
      <mesh filename="package://jacabot_description/meshes/left_wheel_1.stl" scale="0.001 0.001 0.001"/>
    </geometry>
    <material name="silver"/>
  </visual>
  <collision>
    <origin rpy="0 0 0" xyz="-0.116 -0.0 -0.045"/>
    <geometry>
      <mesh filename="package://jacabot_description/meshes/left_wheel_1.stl" scale="0.001 0.001 0.001"/>
    </geometry>
  </collision>
</link>

<link name="right_wheel_1">
  <inertial>
    <origin rpy="0 0 0" xyz="0.0025245376526800006 3.0130693435688574e-08 -6.907443367565325e-07"/>
    <mass value="0.1746608998531855"/>
    <inertia ixx="0.000254" ixy="0.0" ixz="0.0" iyy="0.000128" iyz="0.0" izz="0.000128"/>
  </inertial>
  <visual>
    <origin rpy="0 0 0" xyz="0.116 -0.0 -0.045"/>
    <geometry>
      <mesh filename="package://jacabot_description/meshes/right_wheel_1.stl" scale="0.001 0.001 0.001"/>
    </geometry>
    <material name="silver"/>
  </visual>
  <collision>
    <origin rpy="0 0 0" xyz="0.116 -0.0 -0.045"/>
    <geometry>
      <mesh filename="package://jacabot_description/meshes/right_wheel_1.stl" scale="0.001 0.001 0.001"/>
    </geometry>
  </collision>
</link>

<joint name="lidar_fix" type="fixed">
  <origin rpy="0 0 0" xyz="0.0 -0.048389 0.10325"/>
  <parent link="base_link"/>
  <child link="lidar_1"/>
</joint>

<joint name="camera_fix" type="fixed">
  <origin rpy="0 0 0" xyz="0.0 -0.048389 0.10025"/>
  <parent link="base_link"/>
  <child link="camera_1"/>
</joint>

<joint name="caster_fix" type="fixed">
  <origin rpy="0 0 0" xyz="0.0 0.0 0.03725"/>
  <parent link="base_link"/>
  <child link="ball_caster_1"/>
</joint>

<joint name="left_wheel_joint" type="continuous">
  <origin rpy="0 0 0" xyz="0.116 0.0 0.045"/>
  <parent link="base_link"/>
  <child link="left_wheel_1"/>
  <axis xyz="1.0 -0.0 -0.0"/>
</joint>

<joint name="right_wheel_joint" type="continuous">
  <origin rpy="0 0 0" xyz="-0.116 0.0 0.045"/>
  <parent link="base_link"/>
  <child link="right_wheel_1"/>
  <axis xyz="1.0 0.0 -0.0"/>
</joint>

</robot>
