<?xml version="1.0" encoding="utf-8"?>
<!-- =================================================================================== -->
<!-- |    This document was autogenerated by xacro from jacabot.xacro                  | -->
<!-- |    EDITING THIS FILE BY HAND IS NOT RECOMMENDED                                 | -->
<!-- =================================================================================== -->
<robot name="jacabot">
  <transmission name="left_wheel_joint_tran">
    <type>transmission_interface/SimpleTransmission</type>
    <joint name="left_wheel_joint">
      <hardwareInterface>hardware_interface/EffortJointInterface</hardwareInterface>
    </joint>
    <actuator name="left_wheel_joint_actr">
      <hardwareInterface>hardware_interface/EffortJointInterface</hardwareInterface>
      <mechanicalReduction>1</mechanicalReduction>
    </actuator>
  </transmission>
  <transmission name="right_wheel_joint_tran">
    <type>transmission_interface/SimpleTransmission</type>
    <joint name="right_wheel_joint">
      <hardwareInterface>hardware_interface/EffortJointInterface</hardwareInterface>
    </joint>
    <actuator name="right_wheel_joint_actr">
      <hardwareInterface>hardware_interface/EffortJointInterface</hardwareInterface>
      <mechanicalReduction>1</mechanicalReduction>
    </actuator>
  </transmission>
  <gazebo reference="base_link">
    <material>Gazebo/DarkGrey</material>
  </gazebo>
  <gazebo reference="lidar">
    <material>Gazebo/Grey</material>
  </gazebo>
  <gazebo reference="front_ball_caster">
    <material>Gazebo/DarkGrey</material>
  </gazebo>
  <gazebo reference="left_wheel">
    <material>Gazebo/FlatBlack</material>
  </gazebo>
  <gazebo reference="right_wheel">
    <material>Gazebo/FlatBlack</material>
  </gazebo>
  <gazebo reference="rear_ball_caster">
    <material>Gazebo/DarkGrey</material>
  </gazebo>
  <gazebo reference="temp_sensor">
    <material>Gazebo/Black</material>
  </gazebo>
  <gazebo reference="gas_sensor">
    <material>Gazebo/Black</material>
  </gazebo>
  <gazebo reference="imu">
    <material>Gazebo/Black</material>
  </gazebo>
  <gazebo reference="base_link">
    <mu1>0.2</mu1>
    <mu2>0.2</mu2>
    <selfCollide>true</selfCollide>
    <gravity>true</gravity>
  </gazebo>
  <gazebo reference="lidar">
    <mu1>0.2</mu1>
    <mu2>0.2</mu2>
    <selfCollide>true</selfCollide>
  </gazebo>
  <gazebo reference="front_ball_caster">
    <mu1>0.0</mu1>
    <mu2>0.0</mu2>
    <selfCollide>true</selfCollide>
  </gazebo>
  <gazebo reference="left_wheel">
    <mu1>10.0</mu1>
    <mu2>10.0</mu2>
    <selfCollide>true</selfCollide>
  </gazebo>
  <gazebo reference="right_wheel">
    <mu1>10.0</mu1>
    <mu2>10.0</mu2>
    <selfCollide>true</selfCollide>
  </gazebo>
  <gazebo reference="rear_ball_caster">
    <mu1>0.0</mu1>
    <mu2>0.0</mu2>
    <selfCollide>true</selfCollide>
  </gazebo>
  <gazebo reference="temp_sensor">
    <mu1>0.2</mu1>
    <mu2>0.2</mu2>
    <selfCollide>true</selfCollide>
  </gazebo>
  <gazebo reference="gas_sensor">
    <mu1>0.2</mu1>
    <mu2>0.2</mu2>
    <selfCollide>true</selfCollide>
  </gazebo>
  <gazebo reference="imu">
    <mu1>0.2</mu1>
    <mu2>0.2</mu2>
    <selfCollide>true</selfCollide>
  </gazebo>
  <!-- control plugin -->
  <gazebo>
    <plugin filename="libgazebo_ros_control.so" name="control"/>
  </gazebo>
  <!-- differential driver plugin -->
  <gazebo>
    <plugin filename="libgazebo_ros_diff_drive.so" name="differential_drive_controller">
      <updateRate>100.0</updateRate>
      <leftJoint>left_wheel_joint</leftJoint>
      <rightJoint>right_wheel_joint</rightJoint>
      <wheelSeparation>0.22</wheelSeparation>
      <wheelDiameter>0.09</wheelDiameter>
      <wheelAcceleration>1.0</wheelAcceleration>
      <wheelTorque>0.127</wheelTorque>
      <commandTopic>cmd_vel</commandTopic>
      <odometryTopic>odom</odometryTopic>
      <odometryFrame>odom</odometryFrame>
      <robotBaseFrame>base_footprint</robotBaseFrame>
      <odometrySource>1</odometrySource>
      <publishWheelTF>true</publishWheelTF>
      <publishOdom>true</publishOdom>
      <publishWheelJointState>true</publishWheelJointState>
      <legacyMode>false</legacyMode>
    </plugin>
  </gazebo>
  <!-- lidar plugin -->
  <gazebo reference="lidar">
    <sensor name="lidar" type="depth">
      <visualize>true</visualize>
      <pose>0 0 0 0 0 0</pose>
      <update_rate>100.0</update_rate>
      <camera>
        <horizontal_fov>1.047198</horizontal_fov>
        <image>
          <width>640</width>
          <height>480</height>
          <format>R8G8B8</format>
        </image>
        <clip>
          <near>0.05</near>
          <far>3</far>
        </clip>
      </camera>
      <plugin filename="libgazebo_ros_openni_kinect.so" name="lidar_controller">
        <baseline>0.2</baseline>
        <alwaysOn>true</alwaysOn>
        <updateRate>0.0</updateRate>
        <cameraName>lidar</cameraName>
        <imageTopicName>lidar/color/image_raw</imageTopicName>
        <cameraInfoTopicName>lidar/color/camera_info</cameraInfoTopicName>
        <depthImageTopicName>lidar/depth/image_raw</depthImageTopicName>
        <depthImageInfoTopicName>lidar/depth/camera_info</depthImageInfoTopicName>
        <pointCloudTopicName>lidar/depth/points</pointCloudTopicName>
        <frameName>lidar</frameName>
        <pointCloudCutoff>0.5</pointCloudCutoff>
        <pointCloudCutoffMax>3.0</pointCloudCutoffMax>
        <distortionK1>0.00000001</distortionK1>
        <distortionK2>0.00000001</distortionK2>
        <distortionK3>0.00000001</distortionK3>
        <distortionT1>0.00000001</distortionT1>
        <distortionT2>0.00000001</distortionT2>
        <CxPrime>0</CxPrime>
        <Cx>0</Cx>
        <Cy>0</Cy>
        <focalLength>0</focalLength>
        <hackBaseline>0</hackBaseline>
      </plugin>
    </sensor>
  </gazebo>
  <!-- imu plugin -->
  <gazebo reference="imu">
    <gravity>true</gravity>
    <sensor name="imu_sensor" type="imu">
      <always_on>true</always_on>
      <update_rate>100.0</update_rate>
      <visualize>true</visualize>
      <topic>__default_topic__</topic>
      <plugin filename="libgazebo_ros_imu_sensor.so" name="imu_plugin">
        <topicName>imu</topicName>
        <bodyName>imu</bodyName>
        <updateRateHZ>10.0</updateRateHZ>
        <gaussianNoise>0.0</gaussianNoise>
        <xyzOffset>0 0 0</xyzOffset>
        <rpyOffset>0 0 0</rpyOffset>
        <frameName>imu</frameName>
        <initialOrientationAsReference>false</initialOrientationAsReference>
      </plugin>
      <pose>0 0 0 0 0 0</pose>
    </sensor>
  </gazebo>
  <link name="base_link">
    <inertial>
      <origin rpy="0 0 0" xyz="0.003579933198148806 -8.613056205326139e-05 0.0653504954185309"/>
      <mass value="1.1383292597374606"/>
      <inertia ixx="0.004833" ixy="2e-06" ixz="6.3e-05" iyy="0.005208" iyz="-2e-06" izz="0.008492"/>
    </inertial>
    <visual>
      <origin rpy="0 0 0" xyz="0 0 0"/>
      <geometry>
        <mesh filename="package://jacabot_description/meshes/base_link.stl" scale="0.001 0.001 0.001"/>
      </geometry>
      <!-- <material name="silver"/> -->
    </visual>
    <collision>
      <origin rpy="0 0 0" xyz="0 0 0"/>
      <geometry>
        <mesh filename="package://jacabot_description/meshes/base_link.stl" scale="0.001 0.001 0.001"/>
      </geometry>
    </collision>
  </link>
  <link name="lidar">
    <inertial>
      <origin rpy="0 0 0" xyz="-0.002250102447321716 4.500114002476962e-05 0.045072048933539444"/>
      <mass value="0.6270522917751937"/>
      <inertia ixx="0.002984" ixy="-1e-06" ixz="3e-06" iyy="0.000398" iyz="-0.0" izz="0.002963"/>
    </inertial>
    <visual>
      <origin rpy="0 0 0" xyz="-0.0 -0.0 -0.10025"/>
      <geometry>
        <mesh filename="package://jacabot_description/meshes/lidar.stl" scale="0.001 0.001 0.001"/>
      </geometry>
      <!-- <material name="silver"/> -->
    </visual>
    <collision>
      <origin rpy="0 0 0" xyz="-0.0 -0.0 -0.10025"/>
      <geometry>
        <mesh filename="package://jacabot_description/meshes/lidar.stl" scale="0.001 0.001 0.001"/>
      </geometry>
    </collision>
  </link>
  <link name="front_ball_caster">
    <inertial>
      <origin rpy="0 0 0" xyz="0.07000005407994327 1.3527168224669594e-07 -0.01878123512291732"/>
      <mass value="0.015977116537245855"/>
      <inertia ixx="2e-06" ixy="-0.0" ixz="-0.0" iyy="2e-06" iyz="-0.0" izz="2e-06"/>
    </inertial>
    <visual>
      <origin rpy="0 0 0" xyz="-0.0 -0.0 -0.03525"/>
      <geometry>
        <mesh filename="package://jacabot_description/meshes/front_ball_caster.stl" scale="0.001 0.001 0.001"/>
      </geometry>
      <!-- <material name="silver"/> -->
    </visual>
    <collision>
      <origin rpy="0 0 0" xyz="-0.0 -0.0 -0.03525"/>
      <geometry>
        <mesh filename="package://jacabot_description/meshes/front_ball_caster.stl" scale="0.001 0.001 0.001"/>
      </geometry>
    </collision>
  </link>
  <link name="left_wheel">
    <inertial>
      <origin rpy="0 0 0" xyz="-7.914086335603088e-08 -0.0025244883476263635 6.907443579826089e-07"/>
      <mass value="0.023584783929219873"/>
      <inertia ixx="1.7e-05" ixy="-0.0" ixz="0.0" iyy="3.4e-05" iyz="0.0" izz="1.7e-05"/>
    </inertial>
    <visual>
      <origin rpy="0 0 0" xyz="0.0 -0.116 -0.04525"/>
      <geometry>
        <mesh filename="package://jacabot_description/meshes/left_wheel.stl" scale="0.001 0.001 0.001"/>
      </geometry>
      <!-- <material name="silver"/> -->
    </visual>
    <collision>
      <origin rpy="0 0 0" xyz="0.0 -0.116 -0.04525"/>
      <geometry>
        <mesh filename="package://jacabot_description/meshes/left_wheel.stl" scale="0.001 0.001 0.001"/>
      </geometry>
    </collision>
  </link>
  <link name="right_wheel">
    <inertial>
      <origin rpy="0 0 0" xyz="7.547873737578925e-08 0.0025244883476279456 6.907443579687311e-07"/>
      <mass value="0.023584783929219897"/>
      <inertia ixx="1.7e-05" ixy="-0.0" ixz="-0.0" iyy="3.4e-05" iyz="-0.0" izz="1.7e-05"/>
    </inertial>
    <visual>
      <origin rpy="0 0 0" xyz="0.0 0.116 -0.04525"/>
      <geometry>
        <mesh filename="package://jacabot_description/meshes/right_wheel.stl" scale="0.001 0.001 0.001"/>
      </geometry>
      <!-- <material name="silver"/> -->
    </visual>
    <collision>
      <origin rpy="0 0 0" xyz="0.0 0.116 -0.04525"/>
      <geometry>
        <mesh filename="package://jacabot_description/meshes/right_wheel.stl" scale="0.001 0.001 0.001"/>
      </geometry>
    </collision>
  </link>
  <link name="rear_ball_caster">
    <inertial>
      <origin rpy="0 0 0" xyz="-0.07000005221956881 1.339072818318243e-07 -0.01878121559788453"/>
      <mass value="0.015977143718386187"/>
      <inertia ixx="2e-06" ixy="0.0" ixz="0.0" iyy="2e-06" iyz="-0.0" izz="2e-06"/>
    </inertial>
    <visual>
      <origin rpy="0 0 0" xyz="-0.0 -0.0 -0.03525"/>
      <geometry>
        <mesh filename="package://jacabot_description/meshes/rear_ball_caster.stl" scale="0.001 0.001 0.001"/>
      </geometry>
      <!-- <material name="silver"/> -->
    </visual>
    <collision>
      <origin rpy="0 0 0" xyz="-0.0 -0.0 -0.03525"/>
      <geometry>
        <mesh filename="package://jacabot_description/meshes/rear_ball_caster.stl" scale="0.001 0.001 0.001"/>
      </geometry>
    </collision>
  </link>
  <link name="temp_sensor">
    <inertial>
      <origin rpy="0 0 0" xyz="-0.08805017233647947 0.0499890630824071 0.0030919995294121094"/>
      <mass value="0.010087111752173031"/>
      <inertia ixx="0.0" ixy="-0.0" ixz="-0.0" iyy="1e-06" iyz="-0.0" izz="1e-06"/>
    </inertial>
    <visual>
      <origin rpy="0 0 0" xyz="-0.0 -0.0 -0.10025"/>
      <geometry>
        <mesh filename="package://jacabot_description/meshes/temp_sensor.stl" scale="0.001 0.001 0.001"/>
      </geometry>
      <!-- <material name="silver"/> -->
    </visual>
    <collision>
      <origin rpy="0 0 0" xyz="-0.0 -0.0 -0.10025"/>
      <geometry>
        <mesh filename="package://jacabot_description/meshes/temp_sensor.stl" scale="0.001 0.001 0.001"/>
      </geometry>
    </collision>
  </link>
  <link name="gas_sensor">
    <inertial>
      <origin rpy="0 0 0" xyz="-0.09000000000000005 -0.050000000000000024 0.0060283046418692365"/>
      <mass value="0.018329019530868546"/>
      <inertia ixx="1e-06" ixy="-0.0" ixz="0.0" iyy="1e-06" iyz="-0.0" izz="1e-06"/>
    </inertial>
    <visual>
      <origin rpy="0 0 0" xyz="-0.0 -0.0 -0.10025"/>
      <geometry>
        <mesh filename="package://jacabot_description/meshes/gas_sensor.stl" scale="0.001 0.001 0.001"/>
      </geometry>
      <!-- <material name="silver"/> -->
    </visual>
    <collision>
      <origin rpy="0 0 0" xyz="-0.0 -0.0 -0.10025"/>
      <geometry>
        <mesh filename="package://jacabot_description/meshes/gas_sensor.stl" scale="0.001 0.001 0.001"/>
      </geometry>
    </collision>
  </link>
  <link name="imu">
    <inertial>
      <origin rpy="0 0 0" xyz="-0.04981761579668389 -0.050053964360055596 0.0006843828366709728"/>
      <mass value="0.000732526136495622"/>
      <inertia ixx="0.0" ixy="0.0" ixz="-0.0" iyy="0.0" iyz="0.0" izz="0.0"/>
    </inertial>
    <visual>
      <origin rpy="0 0 0" xyz="-0.0 0.0 -0.04025"/>
      <geometry>
        <mesh filename="package://jacabot_description/meshes/imu.stl" scale="0.001 0.001 0.001"/>
      </geometry>
      <!-- <material name="silver"/> -->
    </visual>
    <collision>
      <origin rpy="0 0 0" xyz="-0.0 0.0 -0.04025"/>
      <geometry>
        <mesh filename="package://jacabot_description/meshes/imu.stl" scale="0.001 0.001 0.001"/>
      </geometry>
    </collision>
  </link>
  <joint name="lidar_fix" type="fixed">
    <origin rpy="0 0 0" xyz="0.0 0.0 0.10025"/>
    <parent link="base_link"/>
    <child link="lidar"/>
  </joint>
  <joint name="front_caster_fix" type="fixed">
    <origin rpy="0 0 0" xyz="0.0 0.0 0.03525"/>
    <parent link="base_link"/>
    <child link="front_ball_caster"/>
  </joint>
  <joint name="left_wheel_joint" type="continuous">
    <origin rpy="0 0 0" xyz="0.0 0.116 0.04525"/>
    <parent link="base_link"/>
    <child link="left_wheel"/>
    <axis xyz="0.0 1.0 -0.0"/>
  </joint>
  <joint name="right_wheel_joint" type="continuous">
    <origin rpy="0 0 0" xyz="0.0 -0.116 0.04525"/>
    <parent link="base_link"/>
    <child link="right_wheel"/>
    <axis xyz="-0.0 1.0 -0.0"/>
  </joint>
  <joint name="rear_caster_fix" type="fixed">
    <origin rpy="0 0 0" xyz="0.0 0.0 0.03525"/>
    <parent link="base_link"/>
    <child link="rear_ball_caster"/>
  </joint>
  <joint name="temp_sensor_fix" type="fixed">
    <origin rpy="0 0 0" xyz="0.0 0.0 0.10025"/>
    <parent link="base_link"/>
    <child link="temp_sensor"/>
  </joint>
  <joint name="gas_sensor_fix" type="fixed">
    <origin rpy="0 0 0" xyz="0.0 0.0 0.10025"/>
    <parent link="base_link"/>
    <child link="gas_sensor"/>
  </joint>
  <joint name="imu_fix" type="fixed">
    <origin rpy="0 0 0" xyz="0.0 0.0 0.04025"/>
    <parent link="base_link"/>
    <child link="imu"/>
  </joint>
</robot>

